02/10/21 (22:47:56) | ERROR: [Errno 2] No such file or directory: '/home/arch/.config/bpytop/themes'
Traceback (most recent call last):
  File "/sbin/bpytop", line 1337, in refresh
    for f in os.listdir(d):
FileNotFoundError: [Errno 2] No such file or directory: '/home/arch/.config/bpytop/themes'
03/10/21 (15:32:24) | ERROR: [Errno 2] No such file or directory: '/home/arch/.config/bpytop/themes'
Traceback (most recent call last):
  File "/sbin/bpytop", line 1337, in refresh
    for f in os.listdir(d):
FileNotFoundError: [Errno 2] No such file or directory: '/home/arch/.config/bpytop/themes'
03/10/21 (15:37:28) | ERROR: [Errno 2] No such file or directory: '/home/arch/.config/bpytop/themes'
Traceback (most recent call last):
  File "/sbin/bpytop", line 1337, in refresh
    for f in os.listdir(d):
FileNotFoundError: [Errno 2] No such file or directory: '/home/arch/.config/bpytop/themes'
03/10/21 (18:07:25) | ERROR: [Errno 2] No such file or directory: '/home/arch/.config/bpytop/themes'
Traceback (most recent call last):
  File "/sbin/bpytop", line 1337, in refresh
    for f in os.listdir(d):
FileNotFoundError: [Errno 2] No such file or directory: '/home/arch/.config/bpytop/themes'
03/10/21 (18:09:31) | ERROR: Input thread failed with exception: (5, 'Input/output error')
Traceback (most recent call last):
  File "/sbin/bpytop", line 985, in _get_key
    input_key = ""
  File "/sbin/bpytop", line 778, in __exit__
    termios.tcsetattr(self.stream, termios.TCSANOW, self.original_stty)
termios.error: (5, 'Input/output error')
08/10/21 (00:32:24) | ERROR: [Errno 2] No such file or directory: '/home/arch/.config/bpytop/themes'
Traceback (most recent call last):
  File "/sbin/bpytop", line 1337, in refresh
    for f in os.listdir(d):
FileNotFoundError: [Errno 2] No such file or directory: '/home/arch/.config/bpytop/themes'
10/10/21 (21:39:02) | ERROR: [Errno 2] No such file or directory: '/home/arch/.config/bpytop/themes'
Traceback (most recent call last):
  File "/sbin/bpytop", line 1337, in refresh
    for f in os.listdir(d):
FileNotFoundError: [Errno 2] No such file or directory: '/home/arch/.config/bpytop/themes'
10/10/21 (21:48:29) | ERROR: Input thread failed with exception: (5, 'Input/output error')
Traceback (most recent call last):
  File "/sbin/bpytop", line 985, in _get_key
    input_key = ""
  File "/sbin/bpytop", line 778, in __exit__
    termios.tcsetattr(self.stream, termios.TCSANOW, self.original_stty)
termios.error: (5, 'Input/output error')
10/10/21 (23:05:03) | ERROR: [Errno 2] No such file or directory: '/home/arch/.config/bpytop/themes'
Traceback (most recent call last):
  File "/sbin/bpytop", line 1337, in refresh
    for f in os.listdir(d):
FileNotFoundError: [Errno 2] No such file or directory: '/home/arch/.config/bpytop/themes'
11/10/21 (00:55:17) | ERROR: [Errno 2] No such file or directory: '/home/arch/.config/bpytop/themes'
Traceback (most recent call last):
  File "/sbin/bpytop", line 1337, in refresh
    for f in os.listdir(d):
FileNotFoundError: [Errno 2] No such file or directory: '/home/arch/.config/bpytop/themes'
13/10/21 (20:52:46) | ERROR: [Errno 2] No such file or directory: '/home/arch/.config/bpytop/themes'
Traceback (most recent call last):
  File "/sbin/bpytop", line 1337, in refresh
    for f in os.listdir(d):
FileNotFoundError: [Errno 2] No such file or directory: '/home/arch/.config/bpytop/themes'
17/10/21 (18:22:05) | ERROR: [Errno 2] No such file or directory: '/home/arch/.config/bpytop/themes'
Traceback (most recent call last):
  File "/sbin/bpytop", line 1337, in refresh
    for f in os.listdir(d):
FileNotFoundError: [Errno 2] No such file or directory: '/home/arch/.config/bpytop/themes'
18/10/21 (17:13:18) | ERROR: [Errno 2] No such file or directory: '/home/arch/.config/bpytop/themes'
Traceback (most recent call last):
  File "/sbin/bpytop", line 1337, in refresh
    for f in os.listdir(d):
FileNotFoundError: [Errno 2] No such file or directory: '/home/arch/.config/bpytop/themes'
18/10/21 (18:24:13) | ERROR: [Errno 2] No such file or directory: '/home/arch/.config/bpytop/themes'
Traceback (most recent call last):
  File "/sbin/bpytop", line 1337, in refresh
    for f in os.listdir(d):
FileNotFoundError: [Errno 2] No such file or directory: '/home/arch/.config/bpytop/themes'
31/10/21 (19:03:31) | ERROR: [Errno 2] No such file or directory: '/home/arch/.config/bpytop/themes'
Traceback (most recent call last):
  File "/sbin/bpytop", line 1337, in refresh
    for f in os.listdir(d):
FileNotFoundError: [Errno 2] No such file or directory: '/home/arch/.config/bpytop/themes'
01/11/21 (20:59:01) | ERROR: [Errno 2] No such file or directory: '/home/arch/.config/bpytop/themes'
Traceback (most recent call last):
  File "/sbin/bpytop", line 1337, in refresh
    for f in os.listdir(d):
FileNotFoundError: [Errno 2] No such file or directory: '/home/arch/.config/bpytop/themes'
01/11/21 (20:59:06) | ERROR: <urlopen error [Errno 101] Network is unreachable>
Traceback (most recent call last):
  File "/usr/lib/python3.9/urllib/request.py", line 1346, in do_open
    h.request(req.get_method(), req.selector, req.data, headers,
  File "/usr/lib/python3.9/http/client.py", line 1279, in request
    self._send_request(method, url, body, headers, encode_chunked)
  File "/usr/lib/python3.9/http/client.py", line 1325, in _send_request
    self.endheaders(body, encode_chunked=encode_chunked)
  File "/usr/lib/python3.9/http/client.py", line 1274, in endheaders
    self._send_output(message_body, encode_chunked=encode_chunked)
  File "/usr/lib/python3.9/http/client.py", line 1034, in _send_output
    self.send(msg)
  File "/usr/lib/python3.9/http/client.py", line 974, in send
    self.connect()
  File "/usr/lib/python3.9/http/client.py", line 1441, in connect
    super().connect()
  File "/usr/lib/python3.9/http/client.py", line 945, in connect
    self.sock = self._create_connection(
  File "/usr/lib/python3.9/socket.py", line 844, in create_connection
    raise err
  File "/usr/lib/python3.9/socket.py", line 832, in create_connection
    sock.connect(sa)
OSError: [Errno 101] Network is unreachable

During handling of the above exception, another exception occurred:

Traceback (most recent call last):
  File "/sbin/bpytop", line 5009, in _checker
    with urllib.request.urlopen("https://github.com/aristocratos/bpytop/raw/master/bpytop.py", timeout=5) as source: # type: ignore
  File "/usr/lib/python3.9/urllib/request.py", line 214, in urlopen
    return opener.open(url, data, timeout)
  File "/usr/lib/python3.9/urllib/request.py", line 517, in open
    response = self._open(req, data)
  File "/usr/lib/python3.9/urllib/request.py", line 534, in _open
    result = self._call_chain(self.handle_open, protocol, protocol +
  File "/usr/lib/python3.9/urllib/request.py", line 494, in _call_chain
    result = func(*args)
  File "/usr/lib/python3.9/urllib/request.py", line 1389, in https_open
    return self.do_open(http.client.HTTPSConnection, req,
  File "/usr/lib/python3.9/urllib/request.py", line 1349, in do_open
    raise URLError(err)
urllib.error.URLError: <urlopen error [Errno 101] Network is unreachable>
03/11/21 (23:15:28) | ERROR: [Errno 2] No such file or directory: '/home/arch/.config/bpytop/themes'
Traceback (most recent call last):
  File "/sbin/bpytop", line 1337, in refresh
    for f in os.listdir(d):
FileNotFoundError: [Errno 2] No such file or directory: '/home/arch/.config/bpytop/themes'
06/11/21 (21:13:37) | ERROR: [Errno 2] No such file or directory: '/home/arch/.config/bpytop/themes'
Traceback (most recent call last):
  File "/sbin/bpytop", line 1337, in refresh
    for f in os.listdir(d):
FileNotFoundError: [Errno 2] No such file or directory: '/home/arch/.config/bpytop/themes'
03/02/22 (09:27:52) | ERROR: [Errno 2] No such file or directory: '/home/arch/.config/bpytop/themes'
Traceback (most recent call last):
  File "/sbin/bpytop", line 1357, in refresh
    for f in os.listdir(d):
FileNotFoundError: [Errno 2] No such file or directory: '/home/arch/.config/bpytop/themes'
03/02/22 (09:28:48) | ERROR: Input thread failed with exception: (5, 'Input/output error')
Traceback (most recent call last):
  File "/sbin/bpytop", line 954, in _get_key
    with Raw(sys.stdin):
  File "/sbin/bpytop", line 798, in __exit__
    termios.tcsetattr(self.stream, termios.TCSANOW, self.original_stty)
termios.error: (5, 'Input/output error')
01/03/22 (19:51:36) | ERROR: [Errno 2] No such file or directory: '/home/arch/.config/bpytop/themes'
Traceback (most recent call last):
  File "/sbin/bpytop", line 1357, in refresh
    for f in os.listdir(d):
FileNotFoundError: [Errno 2] No such file or directory: '/home/arch/.config/bpytop/themes'
08/03/22 (19:47:38) | ERROR: [Errno 2] No such file or directory: '/home/arch/.config/bpytop/themes'
Traceback (most recent call last):
  File "/sbin/bpytop", line 1357, in refresh
    for f in os.listdir(d):
FileNotFoundError: [Errno 2] No such file or directory: '/home/arch/.config/bpytop/themes'
13/03/22 (21:16:42) | ERROR: [Errno 2] No such file or directory: '/home/arch/.config/bpytop/themes'
Traceback (most recent call last):
  File "/sbin/bpytop", line 1357, in refresh
    for f in os.listdir(d):
FileNotFoundError: [Errno 2] No such file or directory: '/home/arch/.config/bpytop/themes'
13/03/22 (21:16:43) | ERROR: <urlopen error [SSL: CERTIFICATE_VERIFY_FAILED] certificate verify failed: self signed certificate in certificate chain (_ssl.c:997)>
Traceback (most recent call last):
  File "/usr/lib/python3.10/urllib/request.py", line 1348, in do_open
    h.request(req.get_method(), req.selector, req.data, headers,
  File "/usr/lib/python3.10/http/client.py", line 1282, in request
    self._send_request(method, url, body, headers, encode_chunked)
  File "/usr/lib/python3.10/http/client.py", line 1328, in _send_request
    self.endheaders(body, encode_chunked=encode_chunked)
  File "/usr/lib/python3.10/http/client.py", line 1277, in endheaders
    self._send_output(message_body, encode_chunked=encode_chunked)
  File "/usr/lib/python3.10/http/client.py", line 1037, in _send_output
    self.send(msg)
  File "/usr/lib/python3.10/http/client.py", line 975, in send
    self.connect()
  File "/usr/lib/python3.10/http/client.py", line 1454, in connect
    self.sock = self._context.wrap_socket(self.sock,
  File "/usr/lib/python3.10/ssl.py", line 512, in wrap_socket
    return self.sslsocket_class._create(
  File "/usr/lib/python3.10/ssl.py", line 1070, in _create
    self.do_handshake()
  File "/usr/lib/python3.10/ssl.py", line 1341, in do_handshake
    self._sslobj.do_handshake()
ssl.SSLCertVerificationError: [SSL: CERTIFICATE_VERIFY_FAILED] certificate verify failed: self signed certificate in certificate chain (_ssl.c:997)

During handling of the above exception, another exception occurred:

Traceback (most recent call last):
  File "/sbin/bpytop", line 5029, in _checker
    with urllib.request.urlopen("https://github.com/aristocratos/bpytop/raw/master/bpytop.py", timeout=5) as source: # type: ignore
  File "/usr/lib/python3.10/urllib/request.py", line 216, in urlopen
    return opener.open(url, data, timeout)
  File "/usr/lib/python3.10/urllib/request.py", line 519, in open
    response = self._open(req, data)
  File "/usr/lib/python3.10/urllib/request.py", line 536, in _open
    result = self._call_chain(self.handle_open, protocol, protocol +
  File "/usr/lib/python3.10/urllib/request.py", line 496, in _call_chain
    result = func(*args)
  File "/usr/lib/python3.10/urllib/request.py", line 1391, in https_open
    return self.do_open(http.client.HTTPSConnection, req,
  File "/usr/lib/python3.10/urllib/request.py", line 1351, in do_open
    raise URLError(err)
urllib.error.URLError: <urlopen error [SSL: CERTIFICATE_VERIFY_FAILED] certificate verify failed: self signed certificate in certificate chain (_ssl.c:997)>
09/06/22 (21:30:59) | ERROR: [Errno 2] No such file or directory: '/home/arch/.config/bpytop/themes'
Traceback (most recent call last):
  File "/sbin/bpytop", line 1357, in refresh
    for f in os.listdir(d):
FileNotFoundError: [Errno 2] No such file or directory: '/home/arch/.config/bpytop/themes'
12/06/22 (12:47:48) | ERROR: [Errno 2] No such file or directory: '/home/arch/.config/bpytop/themes'
Traceback (most recent call last):
  File "/sbin/bpytop", line 1357, in refresh
    for f in os.listdir(d):
FileNotFoundError: [Errno 2] No such file or directory: '/home/arch/.config/bpytop/themes'
12/06/22 (12:50:44) | ERROR: Input thread failed with exception: (5, 'Input/output error')
Traceback (most recent call last):
  File "/sbin/bpytop", line 954, in _get_key
    with Raw(sys.stdin):
  File "/sbin/bpytop", line 798, in __exit__
    termios.tcsetattr(self.stream, termios.TCSANOW, self.original_stty)
termios.error: (5, 'Input/output error')
01/09/22 (20:23:12) | ERROR: [Errno 2] No such file or directory: '/home/saurabh/.config/bpytop/themes'
Traceback (most recent call last):
  File "/usr/bin/bpytop", line 1357, in refresh
    for f in os.listdir(d):
FileNotFoundError: [Errno 2] No such file or directory: '/home/saurabh/.config/bpytop/themes'
